*** Starting uWSGI 2.0.19.1 (64bit) on [Thu Jan 28 05:27:52 2021] ***
compiled with version: 7.5.0 on 03 July 2020 10:45:03
os: Linux-3.10.0-1160.el7.x86_64 #1 SMP Mon Oct 19 16:18:59 UTC 2020
nodename: 4417cfa6001b
machine: x86_64
clock source: unix
detected number of CPU cores: 2
current working directory: /
writing pidfile to /tmp/app5-master.pid
detected binary path: /usr/local/bin/uwsgi
!!! no internal routing support, rebuild with pcre support !!!
uWSGI running as root, you can use --uid/--gid/--chroot options
*** WARNING: you are running uWSGI as root !!! (use the --uid flag) *** 
chdir() to /workspace/
your memory page size is 4096 bytes
detected max file descriptor number: 1048576
lock engine: pthread robust mutexes
thunder lock: disabled (you can enable it with --thunder-lock)
uwsgi socket 0 bound to TCP address :9005 fd 3
uWSGI running as root, you can use --uid/--gid/--chroot options
*** WARNING: you are running uWSGI as root !!! (use the --uid flag) *** 
Python version: 3.6.9 (default, Apr 18 2020, 01:56:04)  [GCC 8.4.0]
Python main interpreter initialized at 0x55770c272cc0
uWSGI running as root, you can use --uid/--gid/--chroot options
*** WARNING: you are running uWSGI as root !!! (use the --uid flag) *** 
python threads support enabled
your server socket listen backlog is limited to 100 connections
your mercy for graceful operations on workers is 60 seconds
mapped 145808 bytes (142 KB) for 1 cores
*** Operational MODE: single process ***
WSGI app 0 (mountpoint='') ready in 1 seconds on interpreter 0x55770c272cc0 pid: 24 (default app)
uWSGI running as root, you can use --uid/--gid/--chroot options
*** WARNING: you are running uWSGI as root !!! (use the --uid flag) *** 
*** uWSGI is running in multiple interpreter mode ***
spawned uWSGI master process (pid: 24)
spawned uWSGI worker 1 (pid: 26, cores: 1)
Python auto-reloader enabled
*** Starting uWSGI 2.0.19.1 (64bit) on [Thu Jan 28 05:29:08 2021] ***
compiled with version: 7.5.0 on 03 July 2020 10:45:03
os: Linux-3.10.0-1160.el7.x86_64 #1 SMP Mon Oct 19 16:18:59 UTC 2020
nodename: 24d9020f96c0
machine: x86_64
clock source: unix
detected number of CPU cores: 2
current working directory: /
writing pidfile to /tmp/app5-master.pid
detected binary path: /usr/local/bin/uwsgi
!!! no internal routing support, rebuild with pcre support !!!
uWSGI running as root, you can use --uid/--gid/--chroot options
*** WARNING: you are running uWSGI as root !!! (use the --uid flag) *** 
chdir() to /workspace/
your memory page size is 4096 bytes
detected max file descriptor number: 1048576
lock engine: pthread robust mutexes
thunder lock: disabled (you can enable it with --thunder-lock)
uwsgi socket 0 bound to TCP address :9005 fd 3
uWSGI running as root, you can use --uid/--gid/--chroot options
*** WARNING: you are running uWSGI as root !!! (use the --uid flag) *** 
Python version: 3.6.9 (default, Apr 18 2020, 01:56:04)  [GCC 8.4.0]
Python main interpreter initialized at 0x55f5600515f0
uWSGI running as root, you can use --uid/--gid/--chroot options
*** WARNING: you are running uWSGI as root !!! (use the --uid flag) *** 
python threads support enabled
your server socket listen backlog is limited to 100 connections
your mercy for graceful operations on workers is 60 seconds
mapped 145808 bytes (142 KB) for 1 cores
*** Operational MODE: single process ***
WSGI app 0 (mountpoint='') ready in 0 seconds on interpreter 0x55f5600515f0 pid: 8 (default app)
uWSGI running as root, you can use --uid/--gid/--chroot options
*** WARNING: you are running uWSGI as root !!! (use the --uid flag) *** 
*** uWSGI is running in multiple interpreter mode ***
spawned uWSGI master process (pid: 8)
spawned uWSGI worker 1 (pid: 10, cores: 1)
Python auto-reloader enabled
*** Starting uWSGI 2.0.19.1 (64bit) on [Thu Jan 28 05:29:51 2021] ***
compiled with version: 7.5.0 on 03 July 2020 10:45:03
os: Linux-3.10.0-1160.el7.x86_64 #1 SMP Mon Oct 19 16:18:59 UTC 2020
nodename: 81465e34b09b
machine: x86_64
clock source: unix
detected number of CPU cores: 2
current working directory: /
writing pidfile to /tmp/app5-master.pid
detected binary path: /usr/local/bin/uwsgi
!!! no internal routing support, rebuild with pcre support !!!
uWSGI running as root, you can use --uid/--gid/--chroot options
*** WARNING: you are running uWSGI as root !!! (use the --uid flag) *** 
chdir() to /workspace/
your memory page size is 4096 bytes
detected max file descriptor number: 1048576
lock engine: pthread robust mutexes
thunder lock: disabled (you can enable it with --thunder-lock)
uwsgi socket 0 bound to TCP address :9005 fd 3
uWSGI running as root, you can use --uid/--gid/--chroot options
*** WARNING: you are running uWSGI as root !!! (use the --uid flag) *** 
Python version: 3.6.9 (default, Apr 18 2020, 01:56:04)  [GCC 8.4.0]
Python main interpreter initialized at 0x563933e545f0
uWSGI running as root, you can use --uid/--gid/--chroot options
*** WARNING: you are running uWSGI as root !!! (use the --uid flag) *** 
python threads support enabled
your server socket listen backlog is limited to 100 connections
your mercy for graceful operations on workers is 60 seconds
mapped 145808 bytes (142 KB) for 1 cores
*** Operational MODE: single process ***
WSGI app 0 (mountpoint='') ready in 0 seconds on interpreter 0x563933e545f0 pid: 8 (default app)
uWSGI running as root, you can use --uid/--gid/--chroot options
*** WARNING: you are running uWSGI as root !!! (use the --uid flag) *** 
*** uWSGI is running in multiple interpreter mode ***
spawned uWSGI master process (pid: 8)
spawned uWSGI worker 1 (pid: 10, cores: 1)
Python auto-reloader enabled
Internal Server Error: /app5/api/mysql/r/
Traceback (most recent call last):
  File "/usr/local/lib/python3.6/dist-packages/django/db/utils.py", line 166, in ensure_defaults
    conn = self.databases[alias]
KeyError: 'slave'

During handling of the above exception, another exception occurred:

Traceback (most recent call last):
  File "/usr/local/lib/python3.6/dist-packages/django/core/handlers/exception.py", line 34, in inner
    response = get_response(request)
  File "/usr/local/lib/python3.6/dist-packages/django/core/handlers/base.py", line 115, in _get_response
    response = self.process_exception_by_middleware(e, request)
  File "/usr/local/lib/python3.6/dist-packages/django/core/handlers/base.py", line 113, in _get_response
    response = wrapped_callback(request, *callback_args, **callback_kwargs)
  File "/usr/local/lib/python3.6/dist-packages/django/views/decorators/csrf.py", line 54, in wrapped_view
    return view_func(*args, **kwargs)
  File "/usr/local/lib/python3.6/dist-packages/django/views/generic/base.py", line 71, in view
    return self.dispatch(request, *args, **kwargs)
  File "/usr/local/lib/python3.6/dist-packages/rest_framework/views.py", line 509, in dispatch
    response = self.handle_exception(exc)
  File "/usr/local/lib/python3.6/dist-packages/rest_framework/views.py", line 469, in handle_exception
    self.raise_uncaught_exception(exc)
  File "/usr/local/lib/python3.6/dist-packages/rest_framework/views.py", line 480, in raise_uncaught_exception
    raise exc
  File "/usr/local/lib/python3.6/dist-packages/rest_framework/views.py", line 506, in dispatch
    response = handler(request, *args, **kwargs)
  File "/usr/local/lib/python3.6/dist-packages/rest_framework/decorators.py", line 50, in handler
    return func(*args, **kwargs)
  File "./db_api/views.py", line 86, in R_data
    if domainlistall.count() == 0:
  File "/usr/local/lib/python3.6/dist-packages/django/db/models/query.py", line 392, in count
    return self.query.get_count(using=self.db)
  File "/usr/local/lib/python3.6/dist-packages/django/db/models/sql/query.py", line 504, in get_count
    number = obj.get_aggregation(using, ['__count'])['__count']
  File "/usr/local/lib/python3.6/dist-packages/django/db/models/sql/query.py", line 488, in get_aggregation
    compiler = outer_query.get_compiler(using)
  File "/usr/local/lib/python3.6/dist-packages/django/db/models/sql/query.py", line 288, in get_compiler
    connection = connections[using]
  File "/usr/local/lib/python3.6/dist-packages/django/db/utils.py", line 198, in __getitem__
    self.ensure_defaults(alias)
  File "/usr/local/lib/python3.6/dist-packages/django/db/utils.py", line 168, in ensure_defaults
    raise ConnectionDoesNotExist("The connection %s doesn't exist" % alias)
django.db.utils.ConnectionDoesNotExist: The connection slave doesn't exist
[pid: 10|app: 0|req: 1/1] 10.10.0.1 () {30 vars in 477 bytes} [Thu Jan 28 05:30:12 2021] GET /app5/api/mysql/r/?tablename=DomainListAll => generated 13485 bytes in 203 msecs (HTTP/1.1 500) 4 headers in 153 bytes (1 switches on core 0)
[uwsgi-python-reloader] module/file ./PJ83_db_api/settings.py has been modified
...gracefully killing workers...
Gracefully killing worker 1 (pid: 10)...
worker 1 buried after 1 seconds
binary reloading uWSGI...
chdir() to /
closing all non-uwsgi socket fds > 2 (max_fd = 1048576)...
found fd 3 mapped to socket 0 (:9005)
running /usr/local/bin/uwsgi
[uWSGI] getting INI configuration from /workspace/PJ83_db_api/uwsgi.ini
*** Starting uWSGI 2.0.19.1 (64bit) on [Thu Jan 28 06:44:05 2021] ***
compiled with version: 7.5.0 on 03 July 2020 10:45:03
os: Linux-3.10.0-1160.el7.x86_64 #1 SMP Mon Oct 19 16:18:59 UTC 2020
nodename: 81465e34b09b
machine: x86_64
clock source: unix
detected number of CPU cores: 2
current working directory: /
detected binary path: /usr/local/bin/uwsgi
!!! no internal routing support, rebuild with pcre support !!!
uWSGI running as root, you can use --uid/--gid/--chroot options
*** WARNING: you are running uWSGI as root !!! (use the --uid flag) *** 
chdir() to /workspace/
your memory page size is 4096 bytes
detected max file descriptor number: 1048576
lock engine: pthread robust mutexes
thunder lock: disabled (you can enable it with --thunder-lock)
uwsgi socket 0 inherited INET address :9005 fd 3
uWSGI running as root, you can use --uid/--gid/--chroot options
*** WARNING: you are running uWSGI as root !!! (use the --uid flag) *** 
Python version: 3.6.9 (default, Apr 18 2020, 01:56:04)  [GCC 8.4.0]
Python main interpreter initialized at 0x55efae43e600
uWSGI running as root, you can use --uid/--gid/--chroot options
*** WARNING: you are running uWSGI as root !!! (use the --uid flag) *** 
python threads support enabled
your server socket listen backlog is limited to 100 connections
your mercy for graceful operations on workers is 60 seconds
mapped 145808 bytes (142 KB) for 1 cores
*** Operational MODE: single process ***
WSGI app 0 (mountpoint='') ready in 1 seconds on interpreter 0x55efae43e600 pid: 8 (default app)
uWSGI running as root, you can use --uid/--gid/--chroot options
*** WARNING: you are running uWSGI as root !!! (use the --uid flag) *** 
*** uWSGI is running in multiple interpreter mode ***
gracefully (RE)spawned uWSGI master process (pid: 8)
spawned uWSGI worker 1 (pid: 13, cores: 1)
Python auto-reloader enabled
*** Starting uWSGI 2.0.19.1 (64bit) on [Thu Jan 28 06:45:15 2021] ***
compiled with version: 7.5.0 on 03 July 2020 10:45:03
os: Linux-3.10.0-1160.el7.x86_64 #1 SMP Mon Oct 19 16:18:59 UTC 2020
nodename: 2f902169e6fb
machine: x86_64
clock source: unix
detected number of CPU cores: 2
current working directory: /
writing pidfile to /tmp/app5-master.pid
detected binary path: /usr/local/bin/uwsgi
!!! no internal routing support, rebuild with pcre support !!!
uWSGI running as root, you can use --uid/--gid/--chroot options
*** WARNING: you are running uWSGI as root !!! (use the --uid flag) *** 
chdir() to /workspace/
your memory page size is 4096 bytes
detected max file descriptor number: 1048576
lock engine: pthread robust mutexes
thunder lock: disabled (you can enable it with --thunder-lock)
uwsgi socket 0 bound to TCP address :9005 fd 3
uWSGI running as root, you can use --uid/--gid/--chroot options
*** WARNING: you are running uWSGI as root !!! (use the --uid flag) *** 
Python version: 3.6.9 (default, Apr 18 2020, 01:56:04)  [GCC 8.4.0]
Python main interpreter initialized at 0x56378f8125f0
uWSGI running as root, you can use --uid/--gid/--chroot options
*** WARNING: you are running uWSGI as root !!! (use the --uid flag) *** 
python threads support enabled
your server socket listen backlog is limited to 100 connections
your mercy for graceful operations on workers is 60 seconds
mapped 145808 bytes (142 KB) for 1 cores
*** Operational MODE: single process ***
WSGI app 0 (mountpoint='') ready in 1 seconds on interpreter 0x56378f8125f0 pid: 8 (default app)
uWSGI running as root, you can use --uid/--gid/--chroot options
*** WARNING: you are running uWSGI as root !!! (use the --uid flag) *** 
*** uWSGI is running in multiple interpreter mode ***
spawned uWSGI master process (pid: 8)
spawned uWSGI worker 1 (pid: 10, cores: 1)
Python auto-reloader enabled
Internal Server Error: /app5/api/mysql/r/
Traceback (most recent call last):
  File "/usr/local/lib/python3.6/dist-packages/pymysql/connections.py", line 571, in connect
    **kwargs)
  File "/usr/lib/python3.6/socket.py", line 724, in create_connection
    raise err
  File "/usr/lib/python3.6/socket.py", line 713, in create_connection
    sock.connect(sa)
OSError: [Errno 113] No route to host

During handling of the above exception, another exception occurred:

Traceback (most recent call last):
  File "/usr/local/lib/python3.6/dist-packages/django/db/backends/base/base.py", line 217, in ensure_connection
    self.connect()
  File "/usr/local/lib/python3.6/dist-packages/django/db/backends/base/base.py", line 195, in connect
    self.connection = self.get_new_connection(conn_params)
  File "/usr/local/lib/python3.6/dist-packages/django/db/backends/mysql/base.py", line 227, in get_new_connection
    return Database.connect(**conn_params)
  File "/usr/local/lib/python3.6/dist-packages/pymysql/__init__.py", line 94, in Connect
    return Connection(*args, **kwargs)
  File "/usr/local/lib/python3.6/dist-packages/pymysql/connections.py", line 327, in __init__
    self.connect()
  File "/usr/local/lib/python3.6/dist-packages/pymysql/connections.py", line 619, in connect
    raise exc
pymysql.err.OperationalError: (2003, "Can't connect to MySQL server on '10.10.0.150' ([Errno 113] No route to host)")

The above exception was the direct cause of the following exception:

Traceback (most recent call last):
  File "/usr/local/lib/python3.6/dist-packages/django/core/handlers/exception.py", line 34, in inner
    response = get_response(request)
  File "/usr/local/lib/python3.6/dist-packages/django/core/handlers/base.py", line 115, in _get_response
    response = self.process_exception_by_middleware(e, request)
  File "/usr/local/lib/python3.6/dist-packages/django/core/handlers/base.py", line 113, in _get_response
    response = wrapped_callback(request, *callback_args, **callback_kwargs)
  File "/usr/local/lib/python3.6/dist-packages/django/views/decorators/csrf.py", line 54, in wrapped_view
    return view_func(*args, **kwargs)
  File "/usr/local/lib/python3.6/dist-packages/django/views/generic/base.py", line 71, in view
    return self.dispatch(request, *args, **kwargs)
  File "/usr/local/lib/python3.6/dist-packages/rest_framework/views.py", line 509, in dispatch
    response = self.handle_exception(exc)
  File "/usr/local/lib/python3.6/dist-packages/rest_framework/views.py", line 469, in handle_exception
    self.raise_uncaught_exception(exc)
  File "/usr/local/lib/python3.6/dist-packages/rest_framework/views.py", line 480, in raise_uncaught_exception
    raise exc
  File "/usr/local/lib/python3.6/dist-packages/rest_framework/views.py", line 506, in dispatch
    response = handler(request, *args, **kwargs)
  File "/usr/local/lib/python3.6/dist-packages/rest_framework/decorators.py", line 50, in handler
    return func(*args, **kwargs)
  File "./db_api/views.py", line 86, in R_data
    if domainlistall.count() == 0:
  File "/usr/local/lib/python3.6/dist-packages/django/db/models/query.py", line 392, in count
    return self.query.get_count(using=self.db)
  File "/usr/local/lib/python3.6/dist-packages/django/db/models/sql/query.py", line 504, in get_count
    number = obj.get_aggregation(using, ['__count'])['__count']
  File "/usr/local/lib/python3.6/dist-packages/django/db/models/sql/query.py", line 489, in get_aggregation
    result = compiler.execute_sql(SINGLE)
  File "/usr/local/lib/python3.6/dist-packages/django/db/models/sql/compiler.py", line 1095, in execute_sql
    cursor = self.connection.cursor()
  File "/usr/local/lib/python3.6/dist-packages/django/db/backends/base/base.py", line 256, in cursor
    return self._cursor()
  File "/usr/local/lib/python3.6/dist-packages/django/db/backends/base/base.py", line 233, in _cursor
    self.ensure_connection()
  File "/usr/local/lib/python3.6/dist-packages/django/db/backends/base/base.py", line 217, in ensure_connection
    self.connect()
  File "/usr/local/lib/python3.6/dist-packages/django/db/utils.py", line 89, in __exit__
    raise dj_exc_value.with_traceback(traceback) from exc_value
  File "/usr/local/lib/python3.6/dist-packages/django/db/backends/base/base.py", line 217, in ensure_connection
    self.connect()
  File "/usr/local/lib/python3.6/dist-packages/django/db/backends/base/base.py", line 195, in connect
    self.connection = self.get_new_connection(conn_params)
  File "/usr/local/lib/python3.6/dist-packages/django/db/backends/mysql/base.py", line 227, in get_new_connection
    return Database.connect(**conn_params)
  File "/usr/local/lib/python3.6/dist-packages/pymysql/__init__.py", line 94, in Connect
    return Connection(*args, **kwargs)
  File "/usr/local/lib/python3.6/dist-packages/pymysql/connections.py", line 327, in __init__
    self.connect()
  File "/usr/local/lib/python3.6/dist-packages/pymysql/connections.py", line 619, in connect
    raise exc
django.db.utils.OperationalError: (2003, "Can't connect to MySQL server on '10.10.0.150' ([Errno 113] No route to host)")
[pid: 10|app: 0|req: 1/1] 10.10.0.1 () {30 vars in 477 bytes} [Thu Jan 28 06:45:41 2021] GET /app5/api/mysql/r/?tablename=DomainListAll => generated 16478 bytes in 3170 msecs (HTTP/1.1 500) 4 headers in 153 bytes (1 switches on core 0)
Internal Server Error: /app5/api/mysql/r/
Traceback (most recent call last):
  File "/usr/local/lib/python3.6/dist-packages/pymysql/connections.py", line 571, in connect
    **kwargs)
  File "/usr/lib/python3.6/socket.py", line 724, in create_connection
    raise err
  File "/usr/lib/python3.6/socket.py", line 713, in create_connection
    sock.connect(sa)
OSError: [Errno 113] No route to host

During handling of the above exception, another exception occurred:

Traceback (most recent call last):
  File "/usr/local/lib/python3.6/dist-packages/django/db/backends/base/base.py", line 217, in ensure_connection
    self.connect()
  File "/usr/local/lib/python3.6/dist-packages/django/db/backends/base/base.py", line 195, in connect
    self.connection = self.get_new_connection(conn_params)
  File "/usr/local/lib/python3.6/dist-packages/django/db/backends/mysql/base.py", line 227, in get_new_connection
    return Database.connect(**conn_params)
  File "/usr/local/lib/python3.6/dist-packages/pymysql/__init__.py", line 94, in Connect
    return Connection(*args, **kwargs)
  File "/usr/local/lib/python3.6/dist-packages/pymysql/connections.py", line 327, in __init__
    self.connect()
  File "/usr/local/lib/python3.6/dist-packages/pymysql/connections.py", line 619, in connect
    raise exc
pymysql.err.OperationalError: (2003, "Can't connect to MySQL server on '10.10.0.150' ([Errno 113] No route to host)")

The above exception was the direct cause of the following exception:

Traceback (most recent call last):
  File "/usr/local/lib/python3.6/dist-packages/django/core/handlers/exception.py", line 34, in inner
    response = get_response(request)
  File "/usr/local/lib/python3.6/dist-packages/django/core/handlers/base.py", line 115, in _get_response
    response = self.process_exception_by_middleware(e, request)
  File "/usr/local/lib/python3.6/dist-packages/django/core/handlers/base.py", line 113, in _get_response
    response = wrapped_callback(request, *callback_args, **callback_kwargs)
  File "/usr/local/lib/python3.6/dist-packages/django/views/decorators/csrf.py", line 54, in wrapped_view
    return view_func(*args, **kwargs)
  File "/usr/local/lib/python3.6/dist-packages/django/views/generic/base.py", line 71, in view
    return self.dispatch(request, *args, **kwargs)
  File "/usr/local/lib/python3.6/dist-packages/rest_framework/views.py", line 509, in dispatch
    response = self.handle_exception(exc)
  File "/usr/local/lib/python3.6/dist-packages/rest_framework/views.py", line 469, in handle_exception
    self.raise_uncaught_exception(exc)
  File "/usr/local/lib/python3.6/dist-packages/rest_framework/views.py", line 480, in raise_uncaught_exception
    raise exc
  File "/usr/local/lib/python3.6/dist-packages/rest_framework/views.py", line 506, in dispatch
    response = handler(request, *args, **kwargs)
  File "/usr/local/lib/python3.6/dist-packages/rest_framework/decorators.py", line 50, in handler
    return func(*args, **kwargs)
  File "./db_api/views.py", line 86, in R_data
    if domainlistall.count() == 0:
  File "/usr/local/lib/python3.6/dist-packages/django/db/models/query.py", line 392, in count
    return self.query.get_count(using=self.db)
  File "/usr/local/lib/python3.6/dist-packages/django/db/models/sql/query.py", line 504, in get_count
    number = obj.get_aggregation(using, ['__count'])['__count']
  File "/usr/local/lib/python3.6/dist-packages/django/db/models/sql/query.py", line 489, in get_aggregation
    result = compiler.execute_sql(SINGLE)
  File "/usr/local/lib/python3.6/dist-packages/django/db/models/sql/compiler.py", line 1095, in execute_sql
    cursor = self.connection.cursor()
  File "/usr/local/lib/python3.6/dist-packages/django/db/backends/base/base.py", line 256, in cursor
    return self._cursor()
  File "/usr/local/lib/python3.6/dist-packages/django/db/backends/base/base.py", line 233, in _cursor
    self.ensure_connection()
  File "/usr/local/lib/python3.6/dist-packages/django/db/backends/base/base.py", line 217, in ensure_connection
    self.connect()
  File "/usr/local/lib/python3.6/dist-packages/django/db/utils.py", line 89, in __exit__
    raise dj_exc_value.with_traceback(traceback) from exc_value
  File "/usr/local/lib/python3.6/dist-packages/django/db/backends/base/base.py", line 217, in ensure_connection
    self.connect()
  File "/usr/local/lib/python3.6/dist-packages/django/db/backends/base/base.py", line 195, in connect
    self.connection = self.get_new_connection(conn_params)
  File "/usr/local/lib/python3.6/dist-packages/django/db/backends/mysql/base.py", line 227, in get_new_connection
    return Database.connect(**conn_params)
  File "/usr/local/lib/python3.6/dist-packages/pymysql/__init__.py", line 94, in Connect
    return Connection(*args, **kwargs)
  File "/usr/local/lib/python3.6/dist-packages/pymysql/connections.py", line 327, in __init__
    self.connect()
  File "/usr/local/lib/python3.6/dist-packages/pymysql/connections.py", line 619, in connect
    raise exc
django.db.utils.OperationalError: (2003, "Can't connect to MySQL server on '10.10.0.150' ([Errno 113] No route to host)")
[pid: 10|app: 0|req: 2/2] 10.10.0.1 () {30 vars in 477 bytes} [Thu Jan 28 06:48:13 2021] GET /app5/api/mysql/r/?tablename=DomainListAll => generated 16478 bytes in 3098 msecs (HTTP/1.1 500) 4 headers in 153 bytes (1 switches on core 0)
*** Starting uWSGI 2.0.19.1 (64bit) on [Thu Jan 28 06:56:19 2021] ***
compiled with version: 7.5.0 on 03 July 2020 10:45:03
os: Linux-3.10.0-1160.el7.x86_64 #1 SMP Mon Oct 19 16:18:59 UTC 2020
nodename: 19453bca708d
machine: x86_64
clock source: unix
detected number of CPU cores: 2
current working directory: /
writing pidfile to /tmp/app5-master.pid
detected binary path: /usr/local/bin/uwsgi
!!! no internal routing support, rebuild with pcre support !!!
uWSGI running as root, you can use --uid/--gid/--chroot options
*** WARNING: you are running uWSGI as root !!! (use the --uid flag) *** 
chdir() to /workspace/
your memory page size is 4096 bytes
detected max file descriptor number: 1048576
lock engine: pthread robust mutexes
thunder lock: disabled (you can enable it with --thunder-lock)
uwsgi socket 0 bound to TCP address :9005 fd 3
uWSGI running as root, you can use --uid/--gid/--chroot options
*** WARNING: you are running uWSGI as root !!! (use the --uid flag) *** 
Python version: 3.6.9 (default, Apr 18 2020, 01:56:04)  [GCC 8.4.0]
Python main interpreter initialized at 0x557add5145f0
uWSGI running as root, you can use --uid/--gid/--chroot options
*** WARNING: you are running uWSGI as root !!! (use the --uid flag) *** 
python threads support enabled
your server socket listen backlog is limited to 100 connections
your mercy for graceful operations on workers is 60 seconds
mapped 145808 bytes (142 KB) for 1 cores
*** Operational MODE: single process ***
WSGI app 0 (mountpoint='') ready in 1 seconds on interpreter 0x557add5145f0 pid: 8 (default app)
uWSGI running as root, you can use --uid/--gid/--chroot options
*** WARNING: you are running uWSGI as root !!! (use the --uid flag) *** 
*** uWSGI is running in multiple interpreter mode ***
spawned uWSGI master process (pid: 8)
spawned uWSGI worker 1 (pid: 10, cores: 1)
Python auto-reloader enabled
[pid: 10|app: 0|req: 1/1] 172.30.0.1 () {30 vars in 478 bytes} [Thu Jan 28 07:02:03 2021] GET /app5/api/mysql/r/?tablename=DomainListAll => generated 23 bytes in 112 msecs (HTTP/1.1 200) 5 headers in 151 bytes (1 switches on core 0)
[uwsgi-python-reloader] module/file ./db_api/models.py has been modified
...gracefully killing workers...
Gracefully killing worker 1 (pid: 10)...
worker 1 buried after 1 seconds
binary reloading uWSGI...
chdir() to /
closing all non-uwsgi socket fds > 2 (max_fd = 1048576)...
found fd 3 mapped to socket 0 (:9005)
running /usr/local/bin/uwsgi
[uWSGI] getting INI configuration from /workspace/PJ83_db_api/uwsgi.ini
*** Starting uWSGI 2.0.19.1 (64bit) on [Thu Jan 28 10:14:46 2021] ***
compiled with version: 7.5.0 on 03 July 2020 10:45:03
os: Linux-3.10.0-1160.el7.x86_64 #1 SMP Mon Oct 19 16:18:59 UTC 2020
nodename: 19453bca708d
machine: x86_64
clock source: unix
detected number of CPU cores: 2
current working directory: /
detected binary path: /usr/local/bin/uwsgi
!!! no internal routing support, rebuild with pcre support !!!
uWSGI running as root, you can use --uid/--gid/--chroot options
*** WARNING: you are running uWSGI as root !!! (use the --uid flag) *** 
chdir() to /workspace/
your memory page size is 4096 bytes
detected max file descriptor number: 1048576
lock engine: pthread robust mutexes
thunder lock: disabled (you can enable it with --thunder-lock)
uwsgi socket 0 inherited INET address :9005 fd 3
uWSGI running as root, you can use --uid/--gid/--chroot options
*** WARNING: you are running uWSGI as root !!! (use the --uid flag) *** 
Python version: 3.6.9 (default, Apr 18 2020, 01:56:04)  [GCC 8.4.0]
Python main interpreter initialized at 0x55f5e8e21600
uWSGI running as root, you can use --uid/--gid/--chroot options
*** WARNING: you are running uWSGI as root !!! (use the --uid flag) *** 
python threads support enabled
your server socket listen backlog is limited to 100 connections
your mercy for graceful operations on workers is 60 seconds
mapped 145808 bytes (142 KB) for 1 cores
*** Operational MODE: single process ***
WSGI app 0 (mountpoint='') ready in 0 seconds on interpreter 0x55f5e8e21600 pid: 8 (default app)
uWSGI running as root, you can use --uid/--gid/--chroot options
*** WARNING: you are running uWSGI as root !!! (use the --uid flag) *** 
*** uWSGI is running in multiple interpreter mode ***
gracefully (RE)spawned uWSGI master process (pid: 8)
spawned uWSGI worker 1 (pid: 13, cores: 1)
Python auto-reloader enabled
*** Starting uWSGI 2.0.19.1 (64bit) on [Thu Jan 28 10:22:42 2021] ***
compiled with version: 7.5.0 on 03 July 2020 10:45:03
os: Linux-3.10.0-1160.el7.x86_64 #1 SMP Mon Oct 19 16:18:59 UTC 2020
nodename: 3e7348e1555d
machine: x86_64
clock source: unix
detected number of CPU cores: 2
current working directory: /
writing pidfile to /tmp/app5-master.pid
detected binary path: /usr/local/bin/uwsgi
!!! no internal routing support, rebuild with pcre support !!!
uWSGI running as root, you can use --uid/--gid/--chroot options
*** WARNING: you are running uWSGI as root !!! (use the --uid flag) *** 
chdir() to /workspace/
your memory page size is 4096 bytes
detected max file descriptor number: 1048576
lock engine: pthread robust mutexes
thunder lock: disabled (you can enable it with --thunder-lock)
uwsgi socket 0 bound to TCP address :9005 fd 3
uWSGI running as root, you can use --uid/--gid/--chroot options
*** WARNING: you are running uWSGI as root !!! (use the --uid flag) *** 
Python version: 3.6.9 (default, Apr 18 2020, 01:56:04)  [GCC 8.4.0]
Python main interpreter initialized at 0x565470f545f0
uWSGI running as root, you can use --uid/--gid/--chroot options
*** WARNING: you are running uWSGI as root !!! (use the --uid flag) *** 
python threads support enabled
your server socket listen backlog is limited to 100 connections
your mercy for graceful operations on workers is 60 seconds
mapped 145808 bytes (142 KB) for 1 cores
*** Operational MODE: single process ***
WSGI app 0 (mountpoint='') ready in 0 seconds on interpreter 0x565470f545f0 pid: 8 (default app)
uWSGI running as root, you can use --uid/--gid/--chroot options
*** WARNING: you are running uWSGI as root !!! (use the --uid flag) *** 
*** uWSGI is running in multiple interpreter mode ***
spawned uWSGI master process (pid: 8)
spawned uWSGI worker 1 (pid: 10, cores: 1)
Python auto-reloader enabled
*** Starting uWSGI 2.0.19.1 (64bit) on [Thu Jan 28 10:23:35 2021] ***
compiled with version: 7.5.0 on 03 July 2020 10:45:03
os: Linux-3.10.0-1160.el7.x86_64 #1 SMP Mon Oct 19 16:18:59 UTC 2020
nodename: 7500e1baf366
machine: x86_64
clock source: unix
detected number of CPU cores: 2
current working directory: /
writing pidfile to /tmp/app5-master.pid
detected binary path: /usr/local/bin/uwsgi
!!! no internal routing support, rebuild with pcre support !!!
uWSGI running as root, you can use --uid/--gid/--chroot options
*** WARNING: you are running uWSGI as root !!! (use the --uid flag) *** 
chdir() to /workspace/
your memory page size is 4096 bytes
detected max file descriptor number: 1048576
lock engine: pthread robust mutexes
thunder lock: disabled (you can enable it with --thunder-lock)
uwsgi socket 0 bound to TCP address :9005 fd 3
uWSGI running as root, you can use --uid/--gid/--chroot options
*** WARNING: you are running uWSGI as root !!! (use the --uid flag) *** 
Python version: 3.6.9 (default, Apr 18 2020, 01:56:04)  [GCC 8.4.0]
Python main interpreter initialized at 0x55bea13cb5f0
uWSGI running as root, you can use --uid/--gid/--chroot options
*** WARNING: you are running uWSGI as root !!! (use the --uid flag) *** 
python threads support enabled
your server socket listen backlog is limited to 100 connections
your mercy for graceful operations on workers is 60 seconds
mapped 145808 bytes (142 KB) for 1 cores
*** Operational MODE: single process ***
WSGI app 0 (mountpoint='') ready in 1 seconds on interpreter 0x55bea13cb5f0 pid: 8 (default app)
uWSGI running as root, you can use --uid/--gid/--chroot options
*** WARNING: you are running uWSGI as root !!! (use the --uid flag) *** 
*** uWSGI is running in multiple interpreter mode ***
spawned uWSGI master process (pid: 8)
spawned uWSGI worker 1 (pid: 10, cores: 1)
Python auto-reloader enabled
